<?xml version="1.0" ?>
<robot name="balance_robot" xmlns:xacro="http://www.ros.org/wiki/xacro">

<xacro:include filename="$(find balance_robot_description)/urdf/materials.xacro" />
<xacro:include filename="$(find balance_robot_description)/urdf/balance_robot.trans" />
<xacro:include filename="$(find balance_robot_description)/urdf/balance_robot.gazebo" />

<link name="base_link"/>

<link name="body_link">
  <inertial>
    <origin rpy="0 0 0" xyz="0 0 0.10"/>
    <!-- initial mass -> mass value="3.047016939610255"/-->
    <mass value="0.8"/>
    <inertia ixx="0.003013" ixy="0.0" ixz="0.0" iyy="0.00194667" iyz="0.0" izz="0.00154667"/>
  </inertial>
  <visual>
    <origin rpy="0 0 0" xyz="0 0 0"/>
    <geometry>
      <mesh filename="package://balance_robot_description/meshes/base_link.stl" scale="0.001 0.001 0.001"/>
    </geometry>
    <material name="silver"/>
  </visual>
  <collision>
    <origin rpy="0 0 0" xyz="0 0 0"/>
    <geometry>
      <mesh filename="package://balance_robot_description/meshes/base_link.stl" scale="0.001 0.001 0.001"/>
    </geometry>
  </collision>
</link>

<link name="imu_link"/>

<link name="left_wheel">
  <inertial>
    <origin rpy="0 0 0" xyz="5.232905343968532e-16 0.013499725279272082 -6.175615574477433e-16"/>
    <!-- initial mass -> mass value="0.700600998578198"/-->
    <mass value="0.05"/>
    <inertia ixx="0.0000541667" ixy="0.0" ixz="0.0" iyy="0.000105625" iyz="0.0" izz="0.0000541667"/>
  </inertial>
  <visual>
    <origin rpy="0 0 0" xyz="-0.0 -0.077266 -0.03301"/>
    <geometry>
      <mesh filename="package://balance_robot_description/meshes/left_wheel_2.stl" scale="0.001 0.001 0.001"/>
    </geometry>
    <material name="silver"/>
  </visual>
  <collision>
    <origin rpy="0 0 0" xyz="-0.0 -0.077266 -0.03301"/>
    <geometry>
      <mesh filename="package://balance_robot_description/meshes/left_wheel_2.stl" scale="0.001 0.001 0.001"/>
    </geometry>
  </collision>
</link>

<link name="right_wheel">
  <inertial>
    <origin rpy="0 0 0" xyz="2.0930055342611735e-15 -0.013500274720727637 6.661338147750939e-16"/>
    <!-- initial mass -> mass value="0.700600998578198"/-->
    <mass value="0.05"/>
    <inertia ixx="0.0000541667" ixy="0.0" ixz="0.0" iyy="0.000105625" iyz="0.0" izz="0.0000541667"/>
  </inertial>
  <visual>
    <origin rpy="0 0 0" xyz="-0.0 0.078734 -0.03301"/>
    <geometry>
      <mesh filename="package://balance_robot_description/meshes/right_wheel_1.stl" scale="0.001 0.001 0.001"/>
    </geometry>
    <material name="silver"/>
  </visual>
  <collision>
    <origin rpy="0 0 0" xyz="-0.0 0.078734 -0.03301"/>
    <geometry>
      <mesh filename="package://balance_robot_description/meshes/right_wheel_1.stl" scale="0.001 0.001 0.001"/>
    </geometry>
  </collision>
</link>

<joint name="base_joint" type="fixed">
  <parent link = "base_link"/>
  <child link = "body_link"/>
  <origin rpy="0 0 0" xyz="0 0 0"/>
</joint>

<joint name="imu_joint" type="fixed">
  <parent link = "base_link"/>
  <child link = "imu_link"/>
  <origin rpy="0 0 0" xyz="0 0 0.150"/>
</joint>

<joint name="left_wheel_joint" type="continuous">
  <origin rpy="0 0 0" xyz="0.0 0.077266 0.03301"/>
  <parent link="base_link"/>
  <child link="left_wheel"/>
  <axis xyz="0.0 1.0 0.0"/>
  <limit velocity="11.52" effort="1.47"/> <!-- vel -> rad/s, effort -> N*m -->
  <dynamics damping="0.1"/>
</joint>

<joint name="right_wheel_joint" type="continuous">
  <origin rpy="0 0 0" xyz="0.0 -0.078734 0.03301"/>
  <parent link="base_link"/>
  <child link="right_wheel"/>
  <axis xyz="0.0 1.0 0.0"/>
  <limit velocity="11.52" effort="1.47"/> <!-- vel -> rad/s, effort -> N*m -->
  <dynamics damping="0.1"/>
</joint>

</robot>
