<?xml version="1.0" encoding="utf-8"?>
<!-- =================================================================================== -->
<!-- |    This document was autogenerated by xacro from balance_robot_simple.urdf.xacro | -->
<!-- |    EDITING THIS FILE BY HAND IS NOT RECOMMENDED                                 | -->
<!-- =================================================================================== -->
<robot name="balance_robot">
  <material name="silver">
    <color rgba="0.700 0.700 0.700 1.000"/>
  </material>
  <material name="Black">
    <color rgba="0.0 0.0 0.0 1.0"/>
  </material>
  <material name="Blue">
    <color rgba="0.0 0.0 0.8 1.0"/>
  </material>
  <material name="Green">
    <color rgba="0.0 0.8 0.0 1.0"/>
  </material>
  <material name="Gray">
    <color rgba="0.7 0.7 0.7 1.0"/>
  </material>
  <material name="DarkGray">
    <color rgba="0.3 0.3 0.3 1.0"/>
  </material>
  <material name="Red">
    <color rgba="0.8 0.0 0.0 1.0"/>
  </material>
  <material name="White">
    <color rgba="1.0 1.0 1.0 1.0"/>
  </material>
  <material name="Yellow">
    <color rgba="0.8 0.8 0.0 1.0"/>
  </material>
  <transmission name="left_wheel_joint_trans" type="SimpleTransmission">
    <type>transmission_interface/SimpleTransmission</type>
    <joint name="left_wheel_joint">
      <hardwareInterface>hardware_interface/EffortJointInterface</hardwareInterface>
    </joint>
    <actuator name="left_wheel_motor">
      <hardwareInterface>hardware_interface/EffortJointInterface</hardwareInterface>
      <mechanicalReduction>90</mechanicalReduction>
    </actuator>
  </transmission>
  <transmission name="right_wheel_joint_trans" type="SimpleTransmission">
    <type>transmission_interface/SimpleTransmission</type>
    <joint name="right_wheel_joint">
      <hardwareInterface>hardware_interface/EffortJointInterface</hardwareInterface>
    </joint>
    <actuator name="right_wheel_motor">
      <hardwareInterface>hardware_interface/EffortJointInterface</hardwareInterface>
      <mechanicalReduction>90</mechanicalReduction>
    </actuator>
  </transmission>
  <gazebo>
    <plugin filename="libgazebo_ros_control.so" name="gazebo_ros_control">
      <robotNamespace>/balance_robot</robotNamespace>
      <robotSimType>gazebo_ros_control/DefaultRobotHWSim</robotSimType>
      <legacyModeNS>false</legacyModeNS>
      <controlPeriod>0.002</controlPeriod>
    </plugin>
  </gazebo>
  <gazebo>
    <plugin filename="libgazebo_ros_p3d.so" name="ground_truth">
      <frameName>world</frameName>
      <bodyName>base_link</bodyName>
      <topicName>/tracker</topicName>
      <updateRate>10.0</updateRate>
    </plugin>
  </gazebo>
  <gazebo reference="base_link">
    <material>Gazebo/Gray</material>
    <mu1>1.0</mu1>
    <mu2>1.0</mu2>
    <!--
  <selfCollide>true</selfCollide>
  <gravity>true</gravity>
  -->
  </gazebo>
  <gazebo reference="imu_link">
    <gravity>true</gravity>
    <sensor name="imu_sensor" type="imu">
      <always_on>true</always_on>
      <update_rate>200</update_rate>
      <visualize>true</visualize>
      <topic>data</topic>
      <plugin filename="libgazebo_ros_imu_sensor.so" name="imu_plugin">
        <topicName>imu_bosch/data_raw</topicName>
        <bodyName>imu_link</bodyName>
        <updateRateHZ>200.0</updateRateHZ>
        <gaussianNoise>0.0</gaussianNoise>
        <xyzOffset>0 0 0</xyzOffset>
        <rpyOffset>0 0 0</rpyOffset>
        <frameName>imu_link</frameName>
      </plugin>
      <pose>0 0 0 0 0 0</pose>
    </sensor>
  </gazebo>
  <gazebo reference="left_wheel">
    <material>Gazebo/Black</material>
    <mu1>2.5</mu1>
    <mu2>2.5</mu2>
    <kp value="50000"/>
    <kd value="10"/>
    <!--
  <selfCollide>true</selfCollide>
  -->
  </gazebo>
  <gazebo reference="right_wheel">
    <material>Gazebo/Black</material>
    <mu1>2.5</mu1>
    <mu2>2.5</mu2>
    <kp value="50000"/>
    <kd value="10"/>
    <!--
  <selfCollide>true</selfCollide>
  -->
  </gazebo>
  <link name="base_link"/>
  <joint name="base_joint" type="fixed">
    <parent link="base_link"/>
    <child link="body_link"/>
    <!--<origin rpy="0 0 0" xyz="0 0 0"/>-->
    <origin rpy="0 0 0" xyz="0 0 0.0325"/>
  </joint>
  <link name="body_link">
    <inertial>
      <origin rpy="0 0 0" xyz="0 0 0.0786"/>
      <mass value="0.926999"/>
      <inertia ixx="5.762E-03" ixy="1.926125E-06" ixz="-4.80363E-06" iyy="4.501E-03" iyz="4.347E-05" izz="1.818E-03"/>
    </inertial>
    <visual>
      <origin rpy="0 0 0" xyz="0 0 0"/>
      <geometry>
        <mesh filename="package://balance_robot_description/meshes/base_link_simple_body_origin.stl" scale="0.001 0.001 0.001"/>
      </geometry>
      <material name="silver"/>
    </visual>
    <collision>
      <origin rpy="0 0 0" xyz="0 0 0"/>
      <geometry>
        <mesh filename="package://balance_robot_description/meshes/base_link_simple_body_origin.stl" scale="0.001 0.001 0.001"/>
      </geometry>
    </collision>
  </link>
  <joint name="imu_joint" type="fixed">
    <parent link="body_link"/>
    <child link="imu_link"/>
    <origin rpy="0 0 0" xyz="0 0 0.145"/>
  </joint>
  <link name="imu_link"/>
  <joint name="left_wheel_joint" type="continuous">
    <parent link="body_link"/>
    <child link="left_wheel"/>
    <origin rpy="0 0 3.14159" xyz="0.0 -0.081 0.0"/>
    <axis xyz="0.0 1.0 0.0"/>
    <limit effort="1.5" velocity="10.47"/>
    <!-- vel->rad/s effort->N*m -->
    <dynamics damping="0.1"/>
  </joint>
  <link name="left_wheel">
    <inertial>
      <origin rpy="0 0 0" xyz="0.0 -0.0114 0.0"/>
      <mass value="0.048361"/>
      <inertia ixx="1.679E-05" ixy="0.0" ixz="0.0" iyy="2.615E-05" iyz="-0.0" izz="1.679E-05"/>
    </inertial>
    <visual>
      <origin rpy="0 0 0" xyz="0 0 0.0"/>
      <geometry>
        <mesh filename="package://balance_robot_description/meshes/wheel_tire_simple_origin.stl" scale="0.001 0.001 0.001"/>
      </geometry>
      <material name="silver"/>
    </visual>
    <collision>
      <origin rpy="0 0 0" xyz="0 0 0"/>
      <geometry>
        <mesh filename="package://balance_robot_description/meshes/wheel_tire_simple_origin.stl" scale="0.001 0.001 0.001"/>
      </geometry>
    </collision>
  </link>
  <joint name="right_wheel_joint" type="continuous">
    <origin rpy="0 0 0" xyz="0.0 0.081 0.0"/>
    <parent link="body_link"/>
    <child link="right_wheel"/>
    <axis xyz="0.0 1.0 0.0"/>
    <limit effort="1.5" velocity="10.47"/>
    <dynamics damping="0.1"/>
  </joint>
  <link name="right_wheel">
    <inertial>
      <origin rpy="0 0 0" xyz="0.0 0.0114 0.0"/>
      <mass value="0.048361"/>
      <inertia ixx="1.679E-05" ixy="0.0" ixz="0.0" iyy="2.615E-05" iyz="-0.0" izz="1.679E-05"/>
    </inertial>
    <visual>
      <origin rpy="0 0 0" xyz="0 0 0"/>
      <geometry>
        <mesh filename="package://balance_robot_description/meshes/wheel_tire_simple_origin.stl" scale="0.001 0.001 0.001"/>
      </geometry>
      <material name="silver"/>
    </visual>
    <collision>
      <origin rpy="0 0 0" xyz="0 0 0"/>
      <geometry>
        <mesh filename="package://balance_robot_description/meshes/wheel_tire_simple_origin.stl" scale="0.001 0.001 0.001"/>
      </geometry>
    </collision>
  </link>
</robot>

