<?xml version="1.0" encoding="utf-8"?>
<!-- =================================================================================== -->
<!-- |    This document was autogenerated by xacro from balance_robot_simple.urdf.xacro | -->
<!-- |    EDITING THIS FILE BY HAND IS NOT RECOMMENDED                                 | -->
<!-- =================================================================================== -->
<robot name="balance_robot">
  <material name="silver">
    <color rgba="0.700 0.700 0.700 1.000"/>
  </material>
  <material name="Black">
    <color rgba="0.0 0.0 0.0 1.0"/>
  </material>
  <material name="Blue">
    <color rgba="0.0 0.0 0.8 1.0"/>
  </material>
  <material name="Green">
    <color rgba="0.0 0.8 0.0 1.0"/>
  </material>
  <material name="Gray">
    <color rgba="0.7 0.7 0.7 1.0"/>
  </material>
  <material name="DarkGray">
    <color rgba="0.3 0.3 0.3 1.0"/>
  </material>
  <material name="Red">
    <color rgba="0.8 0.0 0.0 1.0"/>
  </material>
  <material name="White">
    <color rgba="1.0 1.0 1.0 1.0"/>
  </material>
  <material name="Yellow">
    <color rgba="0.8 0.8 0.0 1.0"/>
  </material>
  <transmission name="left_wheel_joint_trans" type="SimpleTransmission">
    <type>transmission_interface/SimpleTransmission</type>
    <joint name="left_wheel_joint">
      <hardwareInterface>hardware_interface/VelocityJointInterface</hardwareInterface>
    </joint>
    <actuator name="left_wheel_motor">
      <mechanicalReduction>1</mechanicalReduction>
    </actuator>
  </transmission>
  <transmission name="right_wheel_joint_trans" type="SimpleTransmission">
    <type>transmission_interface/SimpleTransmission</type>
    <joint name="right_wheel_joint">
      <hardwareInterface>hardware_interface/VelocityJointInterface</hardwareInterface>
    </joint>
    <actuator name="right_wheel_motor">
      <mechanicalReduction>1</mechanicalReduction>
    </actuator>
  </transmission>
  <gazebo>
    <plugin filename="libgazebo_ros_control.so" name="gazebo_ros_control">
      <robotNamespace>/balance_robot</robotNamespace>
      <robotSimType>gazebo_ros_control/DefaultRobotHWSim</robotSimType>
      <legacyModeNS>true</legacyModeNS>
    </plugin>
  </gazebo>
  <gazebo>
    <plugin filename="libgazebo_ros_p3d.so" name="ground_truth">
      <frameName>world</frameName>
      <bodyName>base_link</bodyName>
      <topicName>/tracker</topicName>
      <updateRate>10.0</updateRate>
    </plugin>
  </gazebo>
  <gazebo reference="base_link">
    <material>Gazebo/Gray</material>
    <mu1>1.0</mu1>
    <mu2>1.0</mu2>
    <!--
  <selfCollide>true</selfCollide>
  <gravity>true</gravity>
  -->
  </gazebo>
  <gazebo reference="imu_link">
    <gravity>true</gravity>
    <sensor name="imu_sensor" type="imu">
      <always_on>true</always_on>
      <update_rate>100</update_rate>
      <visualize>true</visualize>
      <topic>data</topic>
      <plugin filename="libgazebo_ros_imu_sensor.so" name="imu_plugin">
        <topicName>imu/data</topicName>
        <bodyName>imu_link</bodyName>
        <updateRateHZ>10.0</updateRateHZ>
        <gaussianNoise>0.0</gaussianNoise>
        <xyzOffset>0 0 0</xyzOffset>
        <rpyOffset>0 0 0</rpyOffset>
        <frameName>imu_link</frameName>
      </plugin>
      <pose>0 0 0 0 0 0</pose>
    </sensor>
  </gazebo>
  <gazebo reference="left_wheel">
    <material>Gazebo/Black</material>
    <mu1>2.5</mu1>
    <mu2>2.5</mu2>
    <kp value="50000"/>
    <kd value="10"/>
    <!--
  <selfCollide>true</selfCollide>
  -->
  </gazebo>
  <gazebo reference="right_wheel">
    <material>Gazebo/Black</material>
    <mu1>2.5</mu1>
    <mu2>2.5</mu2>
    <kp value="50000"/>
    <kd value="10"/>
    <!--
  <selfCollide>true</selfCollide>
  -->
  </gazebo>
  <link name="base_link"/>
  <link name="body_link">
    <inertial>
      <!-- temp -->
      <origin rpy="0 0 0" xyz="4.1684108266638076e-05 0.000497123586462592 0.1077879171161801"/>
      <!-- initial mass -> mass value="3.047016939610255"/-->
      <mass value="3.047016939610255"/>
      <inertia ixx="0.013885" ixy="0.0" ixz="-5e-06" iyy="0.0102" iyz="1.2e-05" izz="0.00539"/>
    </inertial>
    <visual>
      <origin rpy="0 0 0" xyz="0 0 0"/>
      <geometry>
        <mesh filename="package://balance_robot_description/meshes/base_link_simple_body_origin.stl" scale="0.001 0.001 0.001"/>
      </geometry>
      <material name="silver"/>
    </visual>
    <collision>
      <origin rpy="0 0 0" xyz="0 0 0"/>
      <geometry>
        <mesh filename="package://balance_robot_description/meshes/base_link_simple_body_origin.stl" scale="0.001 0.001 0.001"/>
      </geometry>
    </collision>
  </link>
  <link name="imu_link"/>
  <link name="left_wheel">
    <inertial>
      <!-- temp -->
      <origin rpy="0 0 0" xyz="5.232905343968532e-16 0.013499725279272082 -6.175615574477433e-16"/>
      <mass value="0.700600998578198"/>
      <inertia ixx="0.000227" ixy="0.0" ixz="0.0" iyy="0.000369" iyz="-0.0" izz="0.000227"/>
    </inertial>
    <visual>
      <origin rpy="0 0 0" xyz="0 0 0"/>
      <geometry>
        <mesh filename="package://balance_robot_description/meshes/wheel_tire_simple_origin.stl" scale="0.001 0.001 0.001"/>
      </geometry>
      <material name="silver"/>
    </visual>
    <collision>
      <origin rpy="0 0 0" xyz="0 0 0"/>
      <geometry>
        <mesh filename="package://balance_robot_description/meshes/wheel_tire_simple_origin.stl" scale="0.001 0.001 0.001"/>
      </geometry>
    </collision>
  </link>
  <link name="right_wheel">
    <inertial>
      <!-- temp -->
      <origin rpy="0 0 0" xyz="2.0930055342611735e-15 -0.013500274720727637 6.661338147750939e-16"/>
      <mass value="0.700600998578198"/>
      <inertia ixx="0.000227" ixy="-0.0" ixz="-0.0" iyy="0.000369" iyz="-0.0" izz="0.000227"/>
    </inertial>
    <visual>
      <origin rpy="0 0 0" xyz="0 0 0"/>
      <geometry>
        <mesh filename="package://balance_robot_description/meshes/wheel_tire_simple_origin.stl" scale="0.001 0.001 0.001"/>
      </geometry>
      <material name="silver"/>
    </visual>
    <collision>
      <origin rpy="0 0 0" xyz="0 0 0"/>
      <geometry>
        <mesh filename="package://balance_robot_description/meshes/wheel_tire_simple_origin.stl" scale="0.001 0.001 0.001"/>
      </geometry>
    </collision>
  </link>
  <joint name="base_joint" type="fixed">
    <parent link="base_link"/>
    <child link="body_link"/>
    <origin rpy="0 0 0" xyz="0 0 0"/>
  </joint>
  <joint name="imu_joint" type="fixed">
    <parent link="base_link"/>
    <child link="imu_link"/>
    <origin rpy="0 0 0" xyz="0 0 0.1775"/>
  </joint>
  <joint name="left_wheel_joint" type="continuous">
    <origin rpy="0 0 3.14159" xyz="0.0 -0.081 0.0"/>
    <parent link="base_link"/>
    <child link="left_wheel"/>
    <axis xyz="0.0 1.0 0.0"/>
    <limit effort="1.5" velocity="10.47"/>
    <!-- vel->rad/s effort->N*m -->
    <dynamics damping="0.1"/>
  </joint>
  <joint name="right_wheel_joint" type="continuous">
    <origin rpy="0 0 0" xyz="0.0 0.081 0.0"/>
    <parent link="base_link"/>
    <child link="right_wheel"/>
    <axis xyz="0.0 1.0 0.0"/>
    <limit effort="1.5" velocity="10.47"/>
    <!-- vel->rad/s effort->N*m -->
    <dynamics damping="0.1"/>
  </joint>
</robot>

